<?xml version="1.0" encoding="utf-8"?>
<sdf version='1.7'>
  <model name='rbq3'>
    <self_collide>true</self_collide>
    <!--
    <joint name='world_joint' type='fixed'>
      <child>robot_world</child>
      <parent>world</parent>
    </joint>
    -->
    <!---->
    <joint name='world_joint' type='prismatic'>
      <child>robot_world</child>
      <parent>world</parent>
      <axis>
        <xyz>0 0 1</xyz>
        <dynamics>
          <damping>100</damping>
          <friction>100</friction>
          <spring_reference>0</spring_reference>
          <spring_stiffness>0</spring_stiffness>
        </dynamics>
      </axis>
    </joint>
    
    <link name='robot_world'>
    </link>

    <joint name='rbq3_base_joint' type='universal'>
      <!-- <pose relative_to='world'>0 0 0.5 0 0 0</pose> -->
      <child>trunk</child>
      <parent>robot_world</parent>
      <axis>
        <xyz>1 0 0</xyz>
        <dynamics>
          <damping>1</damping>
          <friction>1</friction>
          <spring_reference>0</spring_reference>
          <spring_stiffness>0</spring_stiffness>
        </dynamics>
        <limit>
          <lower>-1e+16</lower>
          <upper>1e+16</upper>
        </limit>
        <use_parent_model_frame>1</use_parent_model_frame>
      </axis> 
      <axis2>
        <xyz>0 1 0</xyz>
        <limit>
          <lower>-1e+16</lower>
          <upper>1e+16</upper>
        </limit>
        <dynamics>
          <damping>1</damping>
          <friction>1</friction>
          <spring_reference>0</spring_reference>
          <spring_stiffness>0</spring_stiffness>
        </dynamics>
        <use_parent_model_frame>1</use_parent_model_frame>
      </axis2>
    </joint>
    
    <link name='trunk'>
      <!-- <pose relative_to='rbq3_base_joint'>0 0 0 0 0 0</pose> -->
      <inertial>
        <pose>-0.000351 -9e-06 -0.003571 0 -0 0</pose>
        <mass>11.5766</mass>
        <inertia>
          <ixx>0.0668505</ixx>
          <ixy>-6.16234e-05</ixy>
          <ixz>-8.13391e-05</ixz>
          <iyy>0.124923</iyy>
          <iyz>-2.17591e-05</iyz>
          <izz>0.177428</izz>
        </inertia>
      </inertial>
      <collision name='trunk_collision'>
        <pose>0 0 0.0084 0 -0 0</pose>
        <geometry>
          <box>
            <size>0.3 0.15 0.0168</size>
          </box>
        </geometry>
      </collision>
      <visual name='trunk_visual'>
        <pose>0 0 0 0 -0 0</pose>
        <geometry>
          <mesh>
            <scale>1 1 1</scale>
            <uri>model://rbq3_description/meshes/trunk1.dae</uri>
          </mesh>
        </geometry>
        <material>
          <ambient>0 0 0.5 1</ambient>  <!-- light brown -->
        </material>
      </visual>
      <visual name='trunk_fixed_joint_lump__hip_roll_motor_visual_1'>
        <pose>0 0 0 0 -0 0</pose>
        <geometry>
          <mesh>
            <scale>1 1 1</scale>
            <uri>model://rbq3_description/meshes/trunk2.stl</uri>
          </mesh>
        </geometry>
        <material>
          <ambient>0.6 0.5 0 1</ambient>  <!-- light brown -->
        </material>
      </visual>
      <visual name='trunk_fixed_joint_lump__imu_link_visual_2'>
        <pose>-0.1275 0.015 -0.02 0 -0 0</pose>
        <geometry>
          <box>
            <size>0.001 0.001 0.001</size>
          </box>
        </geometry>
      </visual>
      <sensor name='rbq3_base_imu' type='imu'>
        <pose frame=''>-0.1275 0.015 -0.02 0 -0 0</pose>
        <imu>
          <angular_velocity>
            <x> <noise type='none'></noise> </x>
            <y> <noise type='none'></noise> </y>
            <z> <noise type='none'></noise> </z>
          </angular_velocity>
          <linear_acceleration>
            <x> <noise type='none'></noise> </x>
            <y> <noise type='none'></noise> </y>
            <z> <noise type='none'></noise> </z>
          </linear_acceleration>
        </imu>
        <always_on>1</always_on>
        <update_rate>1000</update_rate>
      </sensor>
    </link>

    <joint name='FL_hip_joint' type='revolute'>
      <pose relative_to='trunk'>0.22445 0.07946 0 0 -0 0</pose>
      <parent>trunk</parent>
      <child>FL_hip</child>
      <axis>
        <xyz>1 0 0</xyz>
        <limit>
          <lower>-6.28</lower>
          <upper>6.28</upper>
          <effort>30</effort>
          <velocity>52.4</velocity>
        </limit>
        <dynamics>
          <damping>0.2</damping>
          <friction>0.2</friction>
          <spring_reference>0</spring_reference>
          <spring_stiffness>0</spring_stiffness>
        </dynamics>
      </axis>
    </joint>
    
    <link name='FL_hip'>
      <pose relative_to='FL_hip_joint'>0 0 0 0 -0 0</pose>
      <inertial>
        <pose>-0.00451 0.01758 4e-05 0 -0 0</pose>
        <mass>2.38674</mass>
        <inertia>
          <ixx>0.00343764</ixx>
          <ixy>0.000120457</ixy>
          <ixz>5.6913e-07</ixz>
          <iyy>0.00271864</iyy>
          <iyz>3.82695e-06</iyz>
          <izz>0.00343771</izz>
        </inertia>
      </inertial>
      <collision name='FL_hip_collision'>
        <pose>0 -0.021 0 1.5708 -0 0</pose>
        <geometry>
          <cylinder>
            <length>0.089</length>
            <radius>0.0445</radius>
          </cylinder>
        </geometry>
      </collision>
      <visual name='FL_hip_visual'>
        <pose>0 0 0 0 -0 0</pose>
        <geometry>
          <mesh>
            <scale>1 1 1</scale>
            <uri>model://rbq3_description/meshes/hip.stl</uri>
          </mesh>
        </geometry>
        <material>
          <ambient>0.6 0.5 0 1</ambient>  <!-- light brown -->
        </material>
      </visual>
    </link>
    
    <joint name='FL_thigh_joint' type='revolute'>
      <pose relative_to='FL_hip'>0 0.06995 0 0 -0 0</pose>
      <parent>FL_hip</parent>
      <child>FL_thigh</child>
      <axis>
        <xyz>0 1 0</xyz>
        <limit>
          <lower>-6.28</lower>
          <upper>6.28</upper>
          <effort>30</effort>
          <velocity>28.6</velocity>
        </limit>
        <dynamics>
          <damping>0.2</damping>
          <friction>0.2</friction>
          <spring_reference>0</spring_reference>
          <spring_stiffness>0</spring_stiffness>
        </dynamics>
      </axis>
    </joint>
    
    <link name='FL_thigh'>
      <pose relative_to='FL_thigh_joint'>0 0 0 0 -0 0</pose>
      <inertial>
        <pose>-0.00226 0.00768 -0.04112 0 -0 0</pose>
        <mass>0.67231</mass>
        <inertia>
          <ixx>0.00314694</ixx>
          <ixy>4.35611e-06</ixy>
          <ixz>9.85122e-05</ixz>
          <iyy>0.00342909</iyy>
          <iyz>0.000158744</iyz>
          <izz>0.000636166</izz>
        </inertia>
      </inertial>
      <collision name='FL_thigh_collision'>
        <pose>0 0 -0.1125 0 1.5708 0</pose>
        <geometry>
          <box>
            <size>0.225 0.04 0.04</size>
          </box>
        </geometry>
      </collision>
      <visual name='FL_thigh_visual'>
        <pose>0 0 0 0 -0 0</pose>
        <geometry>
          <mesh>
            <scale>1 1 1</scale>
            <uri>model://rbq3_description/meshes/thigh.dae</uri>
          </mesh>
        </geometry>
        <material>
          <ambient>0.4 0.4 0.4 1</ambient>  <!-- gray -->
        </material>
      </visual>
    </link>
    
    <joint name='FL_calf_joint' type='revolute'>
      <pose relative_to='FL_thigh'>0 0 -0.225 0 -0 0</pose>
      <parent>FL_thigh</parent>
      <child>FL_calf</child>
      <axis>
        <xyz>0 1 0</xyz>
        <limit>
          <lower>-2.77507</lower>
          <upper>-0.610865</upper>
          <effort>30</effort>
          <velocity>28.6</velocity>
        </limit>
        <dynamics>
          <damping>0.2</damping>
          <friction>0.2</friction>
          <spring_reference>0</spring_reference>
          <spring_stiffness>0</spring_stiffness>
        </dynamics>
      </axis>
    </joint>
    
    <link name='FL_calf'>
      <pose relative_to='FL_calf_joint'>0 0 0 0 -0 0</pose>
      <inertial>
        <pose>0.00075 0.00035 -0.08803 0 -0 0</pose>
        <mass>0.173</mass>
        <inertia>
          <ixx>0.00125879</ixx>
          <ixy>1.394e-08</ixy>
          <ixz>-1.34976e-06</ixz>
          <iyy>0.00126646</iyy>
          <iyz>-1.00471e-05</iyz>
          <izz>2.07785e-05</izz>
        </inertia>
      </inertial>
      <collision name='FL_calf_collision'>
        <pose>0 0 -0.1125 0 1.5708 0</pose>
        <geometry>
          <box>
            <size>0.225 0.025 0.025</size>
          </box>
        </geometry>
      </collision>
      <collision name='FL_calf_fixed_joint_lump__FL_foot_collision_1'>
        <pose>0 0 -0.225 0 -0 0</pose>
        <geometry>
          <sphere>
            <radius>0.025</radius>
          </sphere>
        </geometry>
      </collision>
      <visual name='FL_calf_visual'>
        <pose>0 0 0 0 -0 0</pose>
        <geometry>
          <mesh>
            <scale>1 1 1</scale>
            <uri>model://rbq3_description/meshes/calf.stl</uri>
          </mesh>
        </geometry>
      </visual>
      <visual name='FL_calf_fixed_joint_lump__FL_foot_visual_1'>
        <pose>0 0 -0.225 0 -0 0</pose>
        <geometry>
          <sphere>
            <radius>0.025</radius>
          </sphere>
        </geometry>
        <material>
          <ambient>0 0 0 1</ambient>  <!-- black -->
        </material>
      </visual>
    </link>
    
    <joint name='FR_hip_joint' type='revolute'>
      <pose relative_to='trunk'>0.22445 -0.07946 0 0 -0 0</pose>
      <parent>trunk</parent>
      <child>FR_hip</child>
      <axis>
        <xyz>1 0 0</xyz>
        <limit>
          <lower>-6.28</lower>
          <upper>6.28</upper>
          <effort>30</effort>
          <velocity>52.4</velocity>
        </limit>
        <dynamics>
          <damping>0.2</damping>
          <friction>0.2</friction>
          <spring_reference>0</spring_reference>
          <spring_stiffness>0</spring_stiffness>
        </dynamics>
      </axis>
    </joint>
    
    <link name='FR_hip'>
      <pose relative_to='FR_hip_joint'>0 0 0 0 -0 0</pose>
      <inertial>
        <pose>-0.00451 -0.01758 4e-05 0 -0 0</pose>
        <mass>2.38674</mass>
        <inertia>
          <ixx>0.00343764</ixx>
          <ixy>-0.000120457</ixy>
          <ixz>5.6913e-07</ixz>
          <iyy>0.00271864</iyy>
          <iyz>-3.82695e-06</iyz>
          <izz>0.00343771</izz>
        </inertia>
      </inertial>
      <collision name='FR_hip_collision'>
        <pose>0 0.021 0 1.5708 -0 0</pose>
        <geometry>
          <cylinder>
            <length>0.089</length>
            <radius>0.0445</radius>
          </cylinder>
        </geometry>
      </collision>
      <visual name='FR_hip_visual'>
        <pose>0 0 0 -3.14159 0 0</pose>
        <geometry>
          <mesh>
            <scale>1 1 1</scale>
            <uri>model://rbq3_description/meshes/hip.stl</uri>
          </mesh>
        </geometry>
        <material>
          <ambient>0.6 0.5 0 1</ambient>  <!-- light brown -->
        </material>
      </visual>
    </link>
    
    <joint name='FR_thigh_joint' type='revolute'>
      <pose relative_to='FR_hip'>0 -0.06995 0 0 -0 0</pose>
      <parent>FR_hip</parent>
      <child>FR_thigh</child>
      <axis>
        <xyz>0 1 0</xyz>
        <limit>
          <lower>-6.28</lower>
          <upper>6.28</upper>
          <effort>30</effort>
          <velocity>28.6</velocity>
        </limit>
        <dynamics>
          <damping>0.2</damping>
          <friction>0.2</friction>
          <spring_reference>0</spring_reference>
          <spring_stiffness>0</spring_stiffness>
        </dynamics>
      </axis>
    </joint>
    
    <link name='FR_thigh'>
      <pose relative_to='FR_thigh_joint'>0 0 0 0 -0 0</pose>
      <inertial>
        <pose>-0.00226 -0.00768 -0.04112 0 -0 0</pose>
        <mass>0.67231</mass>
        <inertia>
          <ixx>0.00314694</ixx>
          <ixy>-4.35611e-06</ixy>
          <ixz>9.85122e-05</ixz>
          <iyy>0.00342909</iyy>
          <iyz>-0.000158744</iyz>
          <izz>0.000636166</izz>
        </inertia>
      </inertial>
      <collision name='FR_thigh_collision'>
        <pose>0 0 -0.1125 0 1.5708 0</pose>
        <geometry>
          <box>
            <size>0.225 0.04 0.04</size>
          </box>
        </geometry>
      </collision>
      <visual name='FR_thigh_visual'>
        <pose>0 0 0 0 -0 0</pose>
        <geometry>
          <mesh>
            <scale>1 1 1</scale>
            <uri>model://rbq3_description/meshes/thigh.dae</uri>
          </mesh>
        </geometry>
        <material>
          <ambient>0.4 0.4 0.4 1</ambient>  <!-- gray -->
        </material>
      </visual>
    </link>
    
    <joint name='FR_calf_joint' type='revolute'>
      <pose relative_to='FR_thigh'>0 0 -0.225 0 -0 0</pose>
      <parent>FR_thigh</parent>
      <child>FR_calf</child>
      <axis>
        <xyz>0 1 0</xyz>
        <limit>
          <lower>-2.77507</lower>
          <upper>-0.610865</upper>
          <effort>30</effort>
          <velocity>28.6</velocity>
        </limit>
        <dynamics>
          <damping>0.2</damping>
          <friction>0.2</friction>
          <spring_reference>0</spring_reference>
          <spring_stiffness>0</spring_stiffness>
        </dynamics>
      </axis>
    </joint>
    
    <link name='FR_calf'>
      <pose relative_to='FR_calf_joint'>0 0 0 0 -0 0</pose>
      <inertial>
        <pose>0.00075 0.00035 -0.08803 0 -0 0</pose>
        <mass>0.173</mass>
        <inertia>
          <ixx>0.00125879</ixx>
          <ixy>1.394e-08</ixy>
          <ixz>-1.34976e-06</ixz>
          <iyy>0.00126646</iyy>
          <iyz>-1.00471e-05</iyz>
          <izz>2.07785e-05</izz>
        </inertia>
      </inertial>
      <collision name='FR_calf_collision'>
        <pose>0 0 -0.1125 0 1.5708 0</pose>
        <geometry>
          <box>
            <size>0.225 0.025 0.025</size>
          </box>
        </geometry>
      </collision>
      <collision name='FR_calf_fixed_joint_lump__FR_foot_collision_1'>
        <pose>0 0 -0.225 0 -0 0</pose>
        <geometry>
          <sphere>
            <radius>0.025</radius>
          </sphere>
        </geometry>
      </collision>
      <visual name='FR_calf_visual'>
        <pose>0 0 0 0 -0 0</pose>
        <geometry>
          <mesh>
            <scale>1 1 1</scale>
            <uri>model://rbq3_description/meshes/calf.stl</uri>
          </mesh>
        </geometry>
      </visual>
      <visual name='FR_calf_fixed_joint_lump__FR_foot_visual_1'>
        <pose>0 0 -0.225 0 -0 0</pose>
        <geometry>
          <sphere>
            <radius>0.025</radius>
          </sphere>
        </geometry>
        <material>
          <ambient>0 0 0 1</ambient>  <!-- black -->
        </material>
      </visual>
    </link>
    
    <joint name='RL_hip_joint' type='revolute'>
      <pose relative_to='trunk'>-0.22445 0.07946 0 0 -0 0</pose>
      <parent>trunk</parent>
      <child>RL_hip</child>
      <axis>
        <xyz>1 0 0</xyz>
        <limit>
          <lower>-6.28</lower>
          <upper>6.28</upper>
          <effort>30</effort>
          <velocity>52.4</velocity>
        </limit>
        <dynamics>
          <damping>0.2</damping>
          <friction>0.2</friction>
          <spring_reference>0</spring_reference>
          <spring_stiffness>0</spring_stiffness>
        </dynamics>
      </axis>
    </joint>
    
    <link name='RL_hip'>
      <pose relative_to='RL_hip_joint'>0 0 0 0 -0 0</pose>
      <inertial>
        <pose>0.00451 0.01758 4e-05 0 -0 0</pose>
        <mass>2.38674</mass>
        <inertia>
          <ixx>0.00343764</ixx>
          <ixy>-0.000120457</ixy>
          <ixz>-5.6913e-07</ixz>
          <iyy>0.00271864</iyy>
          <iyz>3.82695e-06</iyz>
          <izz>0.00343771</izz>
        </inertia>
      </inertial>
      <collision name='RL_hip_collision'>
        <pose>0 -0.021 0 1.5708 -0 0</pose>
        <geometry>
          <cylinder>
            <length>0.089</length>
            <radius>0.0445</radius>
          </cylinder>
        </geometry>
      </collision>
      <visual name='RL_hip_visual'>
        <pose>0 0 0 3.14159 -0 3.14159</pose>
        <geometry>
          <mesh>
            <scale>1 1 1</scale>
            <uri>model://rbq3_description/meshes/hip.stl</uri>
          </mesh>
        </geometry>
        <material>
          <ambient>0.6 0.5 0 1</ambient>  <!-- light brown -->
        </material>
      </visual>
    </link>
    
    <joint name='RL_thigh_joint' type='revolute'>
      <pose relative_to='RL_hip'>0 0.06995 0 0 -0 0</pose>
      <parent>RL_hip</parent>
      <child>RL_thigh</child>
      <axis>
        <xyz>0 1 0</xyz>
        <limit>
          <lower>-6.28</lower>
          <upper>6.28</upper>
          <effort>30</effort>
          <velocity>28.6</velocity>
        </limit>
        <dynamics>
          <damping>0.2</damping>
          <friction>0.2</friction>
          <spring_reference>0</spring_reference>
          <spring_stiffness>0</spring_stiffness>
        </dynamics>
      </axis>
    </joint>
    
    <link name='RL_thigh'>
      <pose relative_to='RL_thigh_joint'>0 0 0 0 -0 0</pose>
      <inertial>
        <pose>-0.00226 0.00768 -0.04112 0 -0 0</pose>
        <mass>0.67231</mass>
        <inertia>
          <ixx>0.00314694</ixx>
          <ixy>4.35611e-06</ixy>
          <ixz>9.85122e-05</ixz>
          <iyy>0.00342909</iyy>
          <iyz>0.000158744</iyz>
          <izz>0.000636166</izz>
        </inertia>
      </inertial>
      <collision name='RL_thigh_collision'>
        <pose>0 0 -0.1125 0 1.5708 0</pose>
        <geometry>
          <box>
            <size>0.225 0.04 0.04</size>
          </box>
        </geometry>
      </collision>
      <visual name='RL_thigh_visual'>
        <pose>0 0 0 0 -0 0</pose>
        <geometry>
          <mesh>
            <scale>1 1 1</scale>
            <uri>model://rbq3_description/meshes/thigh.dae</uri>
          </mesh>
        </geometry>
        <material>
          <ambient>0.4 0.4 0.4 1</ambient>  <!-- gray -->
        </material>
      </visual>
    </link>
    
    <joint name='RL_calf_joint' type='revolute'>
      <pose relative_to='RL_thigh'>0 0 -0.225 0 -0 0</pose>
      <parent>RL_thigh</parent>
      <child>RL_calf</child>
      <axis>
        <xyz>0 1 0</xyz>
        <limit>
          <lower>-2.77507</lower>
          <upper>-0.610865</upper>
          <effort>30</effort>
          <velocity>28.6</velocity>
        </limit>
        <dynamics>
          <damping>0.2</damping>
          <friction>0.2</friction>
          <spring_reference>0</spring_reference>
          <spring_stiffness>0</spring_stiffness>
        </dynamics>
      </axis>
    </joint>
    
    <link name='RL_calf'>
      <pose relative_to='RL_calf_joint'>0 0 0 0 -0 0</pose>
      <inertial>
        <pose>0.00075 0.00035 -0.08803 0 -0 0</pose>
        <mass>0.173</mass>
        <inertia>
          <ixx>0.00125879</ixx>
          <ixy>1.394e-08</ixy>
          <ixz>-1.34976e-06</ixz>
          <iyy>0.00126646</iyy>
          <iyz>-1.00471e-05</iyz>
          <izz>2.07785e-05</izz>
        </inertia>
      </inertial>
      <collision name='RL_calf_collision'>
        <pose>0 0 -0.125 0 1.5708 0</pose>
        <geometry>
          <box>
            <size>0.225 0.025 0.025</size>
          </box>
        </geometry>
      </collision>
      <collision name='RL_calf_fixed_joint_lump__RL_foot_collision_1'>
        <pose>0 0 -0.225 0 -0 0</pose>
        <geometry>
          <sphere>
            <radius>0.025</radius>
          </sphere>
        </geometry>
      </collision>
      <visual name='RL_calf_visual'>
        <pose>0 0 0 0 -0 0</pose>
        <geometry>
          <mesh>
            <scale>1 1 1</scale>
            <uri>model://rbq3_description/meshes/calf.stl</uri>
          </mesh>
        </geometry>
      </visual>
      <visual name='RL_calf_fixed_joint_lump__RL_foot_visual_1'>
        <pose>0 0 -0.225 0 -0 0</pose>
        <geometry>
          <sphere>
            <radius>0.025</radius>
          </sphere>
        </geometry>
        <material>
          <ambient>0 0 0 1</ambient>  <!-- black -->
        </material>
      </visual>
    </link>
    
    <joint name='RR_hip_joint' type='revolute'>
      <pose relative_to='trunk'>-0.22445 -0.07946 0 0 -0 0</pose>
      <parent>trunk</parent>
      <child>RR_hip</child>
      <axis>
        <xyz>1 0 0</xyz>
        <limit>
          <lower>-6.28</lower>
          <upper>6.28</upper>
          <effort>20</effort>
          <velocity>52.4</velocity>
        </limit>
        <dynamics>
          <damping>0.2</damping>
          <friction>0.2</friction>
          <spring_reference>0</spring_reference>
          <spring_stiffness>0</spring_stiffness>
        </dynamics>
      </axis>
    </joint>
    
    <link name='RR_hip'>
      <pose relative_to='RR_hip_joint'>0 0 0 0 -0 0</pose>
      <inertial>
        <pose>0.00451 -0.01758 4e-05 0 -0 0</pose>
        <mass>2.38674</mass>
        <inertia>
          <ixx>0.00343764</ixx>
          <ixy>0.000120457</ixy>
          <ixz>-5.6913e-07</ixz>
          <iyy>0.00271864</iyy>
          <iyz>-3.82695e-06</iyz>
          <izz>0.00343771</izz>
        </inertia>
      </inertial>
      <collision name='RR_hip_collision'>
        <pose>0 0.021 0 1.5708 -0 0</pose>
        <geometry>
          <cylinder>
            <length>0.089</length>
            <radius>0.0445</radius>
          </cylinder>
        </geometry>
      </collision>
      <visual name='RR_hip_visual'>
        <pose>0 0 0 0 -0 3.14159</pose>
        <geometry>
          <mesh>
            <scale>1 1 1</scale>
            <uri>model://rbq3_description/meshes/hip.stl</uri>
          </mesh>
        </geometry>
        <material>
          <ambient>0.6 0.5 0 1</ambient>  <!-- light brown -->
        </material>
      </visual>
    </link>
    
    <joint name='RR_thigh_joint' type='revolute'>
      <pose relative_to='RR_hip'>0 -0.06995 0 0 -0 0</pose>
      <parent>RR_hip</parent>
      <child>RR_thigh</child>
      <axis>
        <xyz>0 1 0</xyz>
        <limit>
          <lower>-6.28</lower>
          <upper>6.28</upper>
          <effort>30</effort>
          <velocity>28.6</velocity>
        </limit>
        <dynamics>
          <damping>0.2</damping>
          <friction>0.2</friction>
          <spring_reference>0</spring_reference>
          <spring_stiffness>0</spring_stiffness>
        </dynamics>
      </axis>
    </joint>
    
    <link name='RR_thigh'>
      <pose relative_to='RR_thigh_joint'>0 0 0 0 -0 0</pose>
      <inertial>
        <pose>-0.00226 -0.00768 -0.04112 0 -0 0</pose>
        <mass>0.67231</mass>
        <inertia>
          <ixx>0.00314694</ixx>
          <ixy>-4.35611e-06</ixy>
          <ixz>9.85122e-05</ixz>
          <iyy>0.00342909</iyy>
          <iyz>-0.000158744</iyz>
          <izz>0.000636166</izz>
        </inertia>
      </inertial>
      <collision name='RR_thigh_collision'>
        <pose>0 0 -0.1125 0 1.5708 0</pose>
        <geometry>
          <box>
            <size>0.225 0.04 0.04</size>
          </box>
        </geometry>
      </collision>
      <visual name='RR_thigh_visual'>
        <pose>0 0 0 0 -0 0</pose>
        <geometry>
          <mesh>
            <scale>1 1 1</scale>
            <uri>model://rbq3_description/meshes/thigh.dae</uri>
          </mesh>
        </geometry>
        <material>
          <ambient>0.4 0.4 0.4 1</ambient>  <!-- gray -->
        </material>
      </visual>
    </link>
    
    <joint name='RR_calf_joint' type='revolute'>
      <pose relative_to='RR_thigh'>0 0 -0.225 0 -0 0</pose>
      <parent>RR_thigh</parent>
      <child>RR_calf</child>
      <axis>
        <xyz>0 1 0</xyz>
        <limit>
          <lower>-2.77507</lower>
          <upper>-0.610865</upper>
          <effort>30</effort>
          <velocity>28.6</velocity>
        </limit>
        <dynamics>
          <damping>0.2</damping>
          <friction>0.2</friction>
          <spring_reference>0</spring_reference>
          <spring_stiffness>0</spring_stiffness>
        </dynamics>
      </axis>
    </joint>
    
    <link name='RR_calf'>
      <pose relative_to='RR_calf_joint'>0 0 0 0 -0 0</pose>
      <inertial>
        <pose>0.00075 0.00035 -0.08803 0 -0 0</pose>
        <mass>0.173</mass>
        <inertia>
          <ixx>0.00125879</ixx>
          <ixy>1.394e-08</ixy>
          <ixz>-1.34976e-06</ixz>
          <iyy>0.00126646</iyy>
          <iyz>-1.00471e-05</iyz>
          <izz>2.07785e-05</izz>
        </inertia>
      </inertial>
      <collision name='RR_calf_collision'>
        <pose>0 0 -0.1125 0 1.5708 0</pose>
        <geometry>
          <box>
            <size>0.225 0.025 0.025</size>
          </box>
        </geometry>
      </collision>
      <collision name='RR_calf_fixed_joint_lump__RR_foot_collision_1'>
        <pose>0 0 -0.225 0 -0 0</pose>
        <geometry>
          <sphere>
            <radius>0.025</radius>
          </sphere>
        </geometry>
      </collision>
      <visual name='RR_calf_visual'>
        <pose>0 0 0 0 -0 0</pose>
        <geometry>
          <mesh>
            <scale>1 1 1</scale>
            <uri>model://rbq3_description/meshes/calf.stl</uri>
          </mesh>
        </geometry>
      </visual>
      <visual name='RR_calf_fixed_joint_lump__RR_foot_visual_1'>
        <pose>0 0 -0.225 0 -0 0</pose>
        <geometry>
          <sphere>
            <radius>0.025</radius>
          </sphere>
        </geometry>
        <material>
          <ambient>0 0 0 1</ambient>  <!-- black -->
        </material>
      </visual>
    </link>


    <joint name='manipulator_base_joint' type='fixed'>
      <pose relative_to='trunk'>0.15 0 0.05 0 0 0</pose>
      <child>manipulator_base_link</child>
      <parent>trunk</parent>
      <axis>
        <xyz>0 0 0</xyz>
        <limit>
          <lower>-1e+16</lower>
          <upper>1e+16</upper>
        </limit>
        <dynamics>
          <spring_reference>0</spring_reference>
          <spring_stiffness>0</spring_stiffness>
        </dynamics>
        <use_parent_model_frame>1</use_parent_model_frame>
      </axis>
    </joint>
    
    <link name='manipulator_base_link'>
      <pose relative_to='manipulator_base_joint'>0 0 0 0 0 0</pose>
      <!-- <pose>0.15 0 0.05 0 0 0</pose> -->
      <inertial>
        <pose>0 0.000334 0.031072 0 -0 0</pose>
        <mass>0.594687</mass>
        <inertia>
          <ixx>0.000331218</ixx>
          <ixy>-4.35299e-13</ixy>
          <ixz>1.53068e-12</ixz>
          <iyy>0.000348337</iyy>
          <iyz>2.26266e-06</iyz>
          <izz>0.000569437</izz>
        </inertia>
      </inertial>
      <visual name='manipulator_base_link_visual'>
        <pose>0 0 0 0 0 0</pose>
        <geometry>
          <mesh>
            <scale>1 1 1</scale>
            <uri>model://st_arm_description/meshes/stl/base_link.STL</uri>
          </mesh>
        </geometry>
        <material>
          <ambient>0.0 0.0 0.0 1</ambient>
        </material>
      </visual>
      <sensor name="front_camera" type="camera">
        <pose>+0.12 +0 +0 0 0 0</pose>
        <camera>
          <horizontal_fov>2.1</horizontal_fov>
          <image>
            <format>R8G8B8</format>
            <width>848</width>
            <height>480</height>
          </image>
          <clip>
            <near>0.02</near>
            <far>100</far>
          </clip>
          <lens>
            <type>gnomonical</type>
            <scale_to_hfov>true</scale_to_hfov>
            <cutoff_angle>1.5707</cutoff_angle>
            <env_texture_size>512</env_texture_size>
          </lens>
        </camera>
        <plugin name="camera_controller" filename="libgazebo_ros_camera.so">
          <alwaysOn>true</alwaysOn>
          <updateRate>60</updateRate>
          <robotNamespace>gazebo</robotNamespace>
          <cameraName>front_camera</cameraName>
          <imageTopicName>image_raw</imageTopicName>
          <cameraInfoTopicName>camera_info</cameraInfoTopicName>
          <frameName>camera_link</frameName>
        </plugin>
        <visualize>false</visualize>
      </sensor>

      <!--
      <sensor name="IMX219_Back" type="camera">
        <pose>-0.12 +0 +0 0 0 3.141592</pose>
        <camera>
          <horizontal_fov>1.747</horizontal_fov>
          <image>
            <format>R8G8B8</format>
            <width>848</width>
            <height>480</height>
          </image>
          <clip>
            <near>0.02</near>
            <far>100</far>
          </clip>
        </camera>
        <plugin name="camera_controller" filename="libgazebo_ros_camera.so">
          <alwaysOn>true</alwaysOn>
          <updateRate>60</updateRate>
          <cameraName>Back</cameraName>
          <imageTopicName>image_raw</imageTopicName>
          <cameraInfoTopicName>camera_info</cameraInfoTopicName>
          <frameName>camera_link</frameName>
        </plugin>
        <visualize>true</visualize>
      </sensor>      
      <sensor name="IMX219_Left" type="camera">
        <pose>+0 +0.1 +0 0 0 1.570796</pose>
        <camera>
          <horizontal_fov>1.747</horizontal_fov>
          <image>
            <format>R8G8B8</format>
            <width>848</width>
            <height>480</height>
          </image>
          <clip>
            <near>0.02</near>
            <far>100</far>
          </clip>
        </camera>
        <plugin name="camera_controller" filename="libgazebo_ros_camera.so">
          <alwaysOn>true</alwaysOn>
          <updateRate>60</updateRate>
          <cameraName>Left</cameraName>
          <imageTopicName>image_raw</imageTopicName>
          <cameraInfoTopicName>camera_info</cameraInfoTopicName>
          <frameName>camera_link</frameName>
        </plugin>
        <visualize>true</visualize>
      </sensor>
      <sensor name="IMX219_Right" type="camera">
        <pose>+0 -0.1 +0 0 0 4.712388</pose>
        <camera>
          <horizontal_fov>1.747</horizontal_fov>
          <image>
            <format>R8G8B8</format>
            <width>848</width>
            <height>480</height>
          </image>
          <clip>
            <near>0.02</near>
            <far>100</far>
          </clip>
        </camera>
        <plugin name="camera_controller" filename="libgazebo_ros_camera.so">
          <alwaysOn>true</alwaysOn>
          <updateRate>60</updateRate>
          <cameraName>Right</cameraName>
          <imageTopicName>image_raw</imageTopicName>
          <cameraInfoTopicName>camera_info</cameraInfoTopicName>
          <frameName>camera_link</frameName>
        </plugin>
        <visualize>true</visualize>
      </sensor>
      -->
    </link>
    
    <joint name='shoulder_yaw_joint' type='revolute'>
      <pose relative_to='manipulator_base_link'>0 0 0 0 -0 0</pose>
      <parent>manipulator_base_link</parent>
      <child>shoulder_yaw_link</child>
      <axis>
        <xyz>0 0 1</xyz>
        <limit>
          <lower>-3.14</lower>
          <upper>3.14</upper>
          <effort>1</effort>
          <velocity>1</velocity>
        </limit>
        <dynamics>
          <damping>0.1</damping>
          <friction>0.1</friction>
          <spring_reference>0</spring_reference>
          <spring_stiffness>0</spring_stiffness>
        </dynamics>
      </axis>
    </joint>
    
    <link name='shoulder_yaw_link'>
      <pose relative_to='shoulder_yaw_joint'>0 0 0 0 -0 0</pose>
      <inertial>
        <pose>7.6e-05 -0.001995 0.099983 0 -0 0</pose>
        <mass>0.552307</mass>
        <inertia>
          <ixx>0.000249126</ixx>
          <ixy>8.298e-07</ixy>
          <ixz>4.85171e-07</ixz>
          <iyy>0.000406785</iyy>
          <iyz>2.59356e-07</iyz>
          <izz>0.000263429</izz>
        </inertia>
      </inertial>
      <visual name='shoulder_yaw_link_visual'>
        <pose>0 0 0 0 -0 0</pose>
        <geometry>
          <mesh>
            <scale>1 1 1</scale>
            <uri>model://st_arm_description/meshes/stl/shoulder_yaw_link.STL</uri>
          </mesh>
        </geometry>
        <material>
          <ambient>0.7 0.5 0 1</ambient>
        </material>
      </visual>
    </link>
    
    <joint name='shoulder_pitch_joint' type='revolute'>
      <pose relative_to='shoulder_yaw_link'>0 0 0.1019 0 -0 0</pose>
      <parent>shoulder_yaw_link</parent>
      <child>shoulder_pitch_link</child>
      <axis>
        <xyz>0 1 0</xyz>
        <limit>
          <lower>-3.9</lower>
          <upper>0.76</upper>
          <effort>1</effort>
          <velocity>1</velocity>
        </limit>
        <dynamics>
          <damping>0.1</damping>
          <friction>0.1</friction>
          <spring_reference>0</spring_reference>
          <spring_stiffness>0</spring_stiffness>
        </dynamics>
      </axis>
    </joint>
    
    <link name='shoulder_pitch_link'>
      <pose relative_to='shoulder_pitch_joint'>0 0 0 0 -0 0</pose>
      <inertial>
        <pose>0.222042 0.045737 -0 0 -0 0</pose>
        <mass>0.653268</mass>
        <inertia>
          <ixx>0.000286326</ixx>
          <ixy>-1.49184e-07</ixy>
          <ixz>-1.16084e-10</ixz>
          <iyy>0.000648405</iyy>
          <iyz>-1.03192e-10</iyz>
          <izz>0.000486228</izz>
        </inertia>
      </inertial>
      <visual name='shoulder_pitch_link_visual'>
        <pose>0 0 0 0 -0 0</pose>
        <geometry>
          <mesh>
            <scale>1 1 1</scale>
            <uri>model://st_arm_description/meshes/stl/shoulder_pitch_link.STL</uri>
          </mesh>
        </geometry>
        <material>
          <ambient>0.5 0.1 0 1</ambient>
        </material>
      </visual>
    </link>

    <joint name='elbow_pitch_joint' type='revolute'>
      <pose relative_to='shoulder_pitch_link'>0.25 0 0 0 -0 0</pose>
      <parent>shoulder_pitch_link</parent>
      <child>elbow_pitch_link</child>
      <axis>
        <xyz>0 1 0</xyz>
        <limit>
          <lower>-2.9</lower>
          <upper>2.9</upper>
          <effort>1</effort>
          <velocity>1</velocity>
        </limit>
        <dynamics>
          <damping>0.1</damping>
          <friction>0.1</friction>
          <spring_reference>0</spring_reference>
          <spring_stiffness>0</spring_stiffness>
        </dynamics>
      </axis>
    </joint>

    <link name='elbow_pitch_link'>
      <pose relative_to='elbow_pitch_joint'>0 0 0 0 -0 0</pose>
      <inertial>
        <pose>0.170445 0.001209 4.8e-05 0 -0 0</pose>
        <mass>0.170292</mass>
        <inertia>
          <ixx>3.02042e-05</ixx>
          <ixy>-6.35247e-08</ixy>
          <ixz>-2.34242e-10</ixz>
          <iyy>0.000198778</iyy>
          <iyz>-1.0909e-10</iyz>
          <izz>0.000200818</izz>
        </inertia>
      </inertial>
      <visual name='elbow_pitch_link_visual'>
        <pose>0 0 0 0 -0 0</pose>
        <geometry>
          <mesh>
            <scale>1 1 1</scale>
            <uri>model://st_arm_description/meshes/stl/elbow_pitch_link.STL</uri>
          </mesh>
        </geometry>
        <material>
          <ambient>0.5 0.75 0.5 1</ambient>
        </material>
      </visual>
    </link>
    
    <joint name='wrist_pitch_joint' type='revolute'>
      <pose relative_to='elbow_pitch_link'>0.25 0 0 0 -0 0</pose>
      <parent>elbow_pitch_link</parent>
      <child>wrist_pitch_link</child>
      <axis>
        <xyz>0 1 0</xyz>
        <limit>
          <lower>-1.57</lower>
          <upper>1.57</upper>
          <effort>1</effort>
          <velocity>1</velocity>
        </limit>
        <dynamics>
          <damping>0.1</damping>
          <friction>0.1</friction>
          <spring_reference>0</spring_reference>
          <spring_stiffness>0</spring_stiffness>
        </dynamics>
      </axis>
    </joint>
    
    <link name='wrist_pitch_link'>
      <pose relative_to='wrist_pitch_joint'>0 0 0 0 -0 0</pose>
      <inertial>
        <pose>0.042786 -0 0.01133 0 -0 0</pose>
        <mass>0.0923461</mass>
        <inertia>
          <ixx>2.36446e-05</ixx>
          <ixy>2.03859e-14</ixy>
          <ixz>-3.88711e-07</ixz>
          <iyy>2.44308e-05</iyy>
          <iyz>1.60956e-14</iyz>
          <izz>1.6139e-05</izz>
        </inertia>
      </inertial>
      <visual name='wrist_pitch_link_visual'>
        <pose>0 0 0 0 -0 0</pose>
        <geometry>
          <mesh>
            <scale>1 1 1</scale>
            <uri>model://st_arm_description/meshes/stl/wrist_pitch_link.STL</uri>
          </mesh>
        </geometry>
        <material>
          <ambient>0.6 0.3 0.0 1</ambient>
        </material>
      </visual>
    </link>
    
    <joint name='wrist_roll_joint' type='revolute'>
      <pose relative_to='wrist_pitch_link'>0 0 0 0 -0 0</pose>
      <parent>wrist_pitch_link</parent>
      <child>wrist_roll_link</child>
      <axis>
        <xyz>1 0 0</xyz>
        <limit>
          <lower>-1.57</lower>
          <upper>1.57</upper>
          <effort>1</effort>
          <velocity>1</velocity>
        </limit>
        <dynamics>
          <damping>0.1</damping>
          <friction>0.1</friction>
          <spring_reference>0</spring_reference>
          <spring_stiffness>0</spring_stiffness>
        </dynamics>
      </axis>
    </joint>
    
    <link name='wrist_roll_link'>
      <pose relative_to='wrist_roll_joint'>0 0 0 0 -0 0</pose>
      <inertial>
        <pose>0.091375 0 0.000362 0 -0 0</pose>
        <mass>0.0869629</mass>
        <inertia>
          <ixx>1.41812e-05</ixx>
          <ixy>-9.57639e-15</ixy>
          <ixz>2.92507e-09</ixz>
          <iyy>2.29933e-05</iyy>
          <iyz>1.70366e-16</iyz>
          <izz>1.9671e-05</izz>
        </inertia>
      </inertial>
      <visual name='wrist_roll_link_visual'>
        <pose>0 0 0 0 -0 0</pose>
        <geometry>
          <mesh>
            <scale>1 1 1</scale>
            <uri>model://st_arm_description/meshes/stl/wrist_roll_link.STL</uri>
          </mesh>
        </geometry>
        <material>
          <ambient>0.7 0.2 1 1</ambient>
        </material>
      </visual>
    </link>
    
    <joint name='wrist_yaw_joint' type='revolute'>
      <pose relative_to='wrist_roll_link'>0.1045 0 0 0 -0 0</pose>
      <parent>wrist_roll_link</parent>
      <child>wrist_yaw_link</child>
      <axis>
        <xyz>0 0 1</xyz>
        <limit>
          <lower>-2</lower>
          <upper>2</upper>
          <effort>1</effort>
          <velocity>1</velocity>
        </limit>
        <dynamics>
          <damping>0.1</damping>
          <friction>0.1</friction>
          <spring_reference>0</spring_reference>
          <spring_stiffness>0</spring_stiffness>
        </dynamics>
      </axis>
    </joint>
    
    <link name='wrist_yaw_link'>
      <pose relative_to='wrist_yaw_joint'>0 0 0 0 -0 0</pose>
      <inertial>
        <pose>0.052108 0.000348 0.022185 0 -0 0</pose>
        <mass>0.148763</mass>
        <inertia>
          <ixx>6.90068e-05</ixx>
          <ixy>2.51082e-07</ixy>
          <ixz>4.81485e-07</ixz>
          <iyy>3.3479e-05</iyy>
          <iyz>-1.73104e-09</iyz>
          <izz>5.62471e-05</izz>
        </inertia>
      </inertial>
      <visual name='wrist_yaw_link_visual'>
        <pose>0 0 0 0 -0 0</pose>
        <geometry>
          <mesh>
            <scale>1 1 1</scale>
            <uri>model://st_arm_description/meshes/stl/wrist_yaw_link.STL</uri>
          </mesh>
        </geometry>
        <material>
          <ambient>0.1 0.1 0.1 1</ambient>
        </material>
      </visual>
      <sensor name="end_effector_camera" type="camera">
        <pose>0.07 0 0.08 0 0.5 0</pose>
        <camera>
          <horizontal_fov>2.1</horizontal_fov>
          <image>
            <format>R8G8B8</format>
            <width>848</width>
            <height>480</height>
          </image>
          <clip>
            <near>0.02</near>
            <far>100</far>
          </clip>
          <lens>
            <type>gnomonical</type>
            <scale_to_hfov>true</scale_to_hfov>
            <cutoff_angle>1.5707</cutoff_angle>
            <env_texture_size>512</env_texture_size>
          </lens>
        </camera>
        <plugin name="camera_controller" filename="libgazebo_ros_camera.so">
          <alwaysOn>true</alwaysOn>
          <updateRate>60</updateRate>
          <robotNamespace>gazebo</robotNamespace>
          <cameraName>ee_camera</cameraName>
          <imageTopicName>image_raw</imageTopicName>
          <cameraInfoTopicName>camera_info</cameraInfoTopicName>
          <frameName>camera_link</frameName>
        </plugin>
        <visualize>false</visualize>
      </sensor>

      <!--
      <sensor name="D435" type="depth">
        <pose>+0.07 +0 +0.05 0 0 0</pose>
        <camera>
          <horizontal_fov>1.747</horizontal_fov>
          <image>
            <format>B8G8R8</format>
            <width>848</width>
            <height>480</height>
          </image>
          <clip>
            <near>0.02</near>
            <far>100</far>
          </clip>
        </camera>
        <plugin name="camera_plugin" filename="libgazebo_ros_openni_kinect.so">
          <baseline>0.2</baseline>
          <alwaysOn>true</alwaysOn>
          <updateRate>0.0</updateRate>
          <cameraName>camera_ir</cameraName>
          <imageTopicName>/D435_RGB/image_raw</imageTopicName>
          <cameraInfoTopicName>/camera/color/camera_info</cameraInfoTopicName>
          <depthImageTopicName>/D435_Depth/image_raw</depthImageTopicName>
          <depthImageCameraInfoTopicName>/camera/depth/camera_info</depthImageCameraInfoTopicName>
          <pointCloudTopicName>/camera/depth/points</pointCloudTopicName>
          <frameName>camera_link</frameName>
          <pointCloudCutoff>0.2</pointCloudCutoff>
          <pointCloudCutoffMax>8.0</pointCloudCutoffMax>
          <min_depth>0.2</min_depth>
          <max_depth>8.0</max_depth>
          <distortionK1>0</distortionK1>
          <distortionK2>0</distortionK2>
          <distortionK3>0</distortionK3>
          <distortionT1>0</distortionT1>
          <distortionT2>0</distortionT2>
          <CxPrime>0</CxPrime>
          <Cx>0</Cx>
          <Cy>0</Cy>
          <focalLength>0</focalLength>
          <hackBaseline>0</hackBaseline>
        </plugin>
        <plugin name="camera_controller" filename="libgazebo_ros_camera.so">
          <alwaysOn>true</alwaysOn>
          <updateRate>60</updateRate>
          <cameraName>D435_depth</cameraName>
          <imageTopicName>image_raw</imageTopicName>
          <cameraInfoTopicName>camera_info</cameraInfoTopicName>
          <frameName>camera_link_optical</frameName>
        </plugin>
        <visualize>true</visualize>
      </sensor>
      -->

    </link>

    <joint name='gripper_left_joint' type='prismatic'>
      <pose relative_to='wrist_yaw_link'>0.083595 0 0 0 -0 0</pose>
      <parent>wrist_yaw_link</parent>
      <child>gripper_left_link</child>
      <axis>
        <xyz>0 -1 0</xyz>
        <limit>
          <lower>-0.03</lower>
          <upper>0</upper>
          <effort>1</effort>
          <velocity>1</velocity>
        </limit>
        <dynamics>
          <damping>0.1</damping>
          <friction>0.1</friction>
          <spring_reference>0</spring_reference>
          <spring_stiffness>0</spring_stiffness>
        </dynamics>
      </axis>
    </joint>

    <link name='gripper_left_link'>
      <pose relative_to='gripper_left_joint'>0 0 0 0 -0 0</pose>

      <!--
      <inertial>
        <pose>0 0 0 0 -0 0</pose>
        <mass>0.0001</mass>
        <inertia>
          <ixx>1e-16</ixx>
          <ixy>1e-16</ixy>
          <ixz>1e-16</ixz>
          <iyy>1e-16</iyy>
          <iyz>1e-16</iyz>
          <izz>1e-16</izz>
        </inertia>
      </inertial>
      -->
      <!--
      <inertial>
        <pose>0 0 0 0 -0 0</pose>
        <mass>0.001</mass>
        <inertia>
          <ixx>1e-8</ixx>
          <ixy>1e-8</ixy>
          <ixz>1e-8</ixz>
          <iyy>1e-10</iyy>
          <iyz>1e-10</iyz>
          <izz>1e-10</izz>
        </inertia>
      </inertial>
      -->

      <!---->
      <inertial>
        <pose>0.011191 0.017208 -0 0 -0 0</pose>
        <mass>0.0151655</mass>
        <inertia>
          <ixx>1.52745e-06</ixx>
          <ixy>1.20106e-06</ixy>
          <ixz>3.87211e-18</ixz>
          <iyy>7.43136e-06</iyy>
          <iyz>-6.58552e-19</iyz>
          <izz>8.50839e-06</izz>
        </inertia>
      </inertial>
      
      <!---->
      <collision name='gripper_left_link_collision'>
        <pose>0.0425 0.0 0 0 0 0</pose>
        <geometry>
          <box>
            <size>0.085 0.005 0.02</size>
          </box>
        </geometry>
        
        <surface>
          <!--NOTE: Used dynamic friction of clean dry plastic cube on a plastic surface
          (i.e. Polyethylene) see https://www.engineeringtoolbox.com/friction-coefficients-d_778.html
          -->
          <friction>
            <ode>
              <mu>1.2</mu>
              <mu2>1.2</mu2>
            </ode>
          </friction>
          <contact>
            <collide_bitmask>1</collide_bitmask>
            <ode>
              <kp>1e+06</kp>
              <kd>1e+06</kd>
              <max_vel>1</max_vel>
              <min_depth>0.002</min_depth>
            </ode>
            <bullet>
              <kp>1e+06</kp>
              <kd>1e+06</kd>
            </bullet>
          </contact>
        </surface>
        
      </collision>
      

      <visual name='gripper_left_link_visual'>
        <!---->
        <pose>0 0 0 0 -0 0</pose>
        <geometry>
          <mesh>
            <scale>1 1 1</scale>
            <uri>model://st_arm_description/meshes/stl/gripper_left_link.STL</uri>
          </mesh>          
        </geometry>
        <material>
          <ambient>1 0 0 1</ambient>
        </material>
      </visual>
    </link>

    <joint name='gripper_right_joint' type='prismatic'>
      <pose relative_to='wrist_yaw_link'>0.083595 0 0 0 -0 0</pose>
      <parent>wrist_yaw_link</parent>
      <child>gripper_right_link</child>
      <axis>
        <xyz>0 1 0</xyz>
        <limit>
          <lower>-0.03</lower>
          <upper>0</upper>
          <effort>1</effort>
          <velocity>1</velocity>
        </limit>
        <dynamics>
          <damping>0.1</damping>
          <friction>0.1</friction>
          <spring_reference>0</spring_reference>
          <spring_stiffness>0</spring_stiffness>
        </dynamics>
      </axis>
    </joint>

    <link name='gripper_right_link'>
      <pose relative_to='gripper_right_joint'>0 0 0 0 -0 0</pose>
      <inertial>
        <pose>0.011191 -0.017208 0 0 -0 0</pose>
        <mass>0.0151655</mass>
        <inertia>
          <ixx>1.52745e-06</ixx>
          <ixy>-1.20106e-06</ixy>
          <ixz>1.01095e-20</ixz>
          <iyy>7.43136e-06</iyy>
          <iyz>9.01849e-21</iyz>
          <izz>8.50839e-06</izz>
        </inertia>
      </inertial>
      
      <!---->
      <collision name='gripper_right_link_collision'>
        <pose>0.0425 -0.0 0 0 0 0</pose>
        <geometry>
          <box>
            <size>0.085 0.005 0.02</size>
          </box>
        </geometry>
        
        <surface>
          <!--NOTE: Used dynamic friction of clean dry plastic cube on a plastic surface
          (i.e. Polyethylene) see https://www.engineeringtoolbox.com/friction-coefficients-d_778.html
          -->
          <friction>
            <ode>
              <mu>1.2</mu>
              <mu2>1.2</mu2>
            </ode>
          </friction>
          <contact>
            <collide_bitmask>1</collide_bitmask>
            <ode>
              <kp>1e+06</kp>
              <kd>1e+06</kd>
              <max_vel>1</max_vel>
              <min_depth>0.002</min_depth>
            </ode>
            <bullet>
              <kp>1e+06</kp>
              <kd>1e+06</kd>
            </bullet>
          </contact>
        </surface>

      </collision>
      
      <visual name='gripper_right_link_visual'>
        <pose>0 0 0 0 -0 0</pose>
        <geometry>
          <mesh>
            <scale>1 1 1</scale>
            <uri>model://st_arm_description/meshes/stl/gripper_right_link.STL</uri>
          </mesh>
        </geometry>
        <material>
          <ambient>1 0 0 1</ambient>
        </material>
      </visual>
    </link>

    <!--
    <gripper name='grasping'>
      <gripper_link>gripper_left_link</gripper_link>
      <gripper_link>gripper_right_link</gripper_link>
      <palm_link>wrist_yaw_link</palm_link>
    </gripper>
    -->

  </model>
</sdf>
